(function() {
  'use strict';

  function respondAfter100ms(x) {
    return new Promise((resolve, reject) => {
      setTimeout(() => {
        if (x >= 0) {
          resolve(x);
        } else {
          reject('ðŸ’€ðŸ’€ðŸ’€');
        }
      }, 100);
    });
  }

  function addToSix() {
    let sum = 0;
    return respondAfter100ms(1)
      .then(one => {
        sum += one;
        return respondAfter100ms(2);
      })
      .then(two => {
        sum += two;
        return respondAfter100ms(3);
      })
      .then(four => {
        sum += four;
        return sum;
      });
  }

  addToSix().then(sum => {
    console.log('addToSix returns', sum);
  });

  /*
  ========================================================================
  ðŸ‘‰ Rewrite `addToSix` function in a new function with async / await only
  ðŸ‘‰ Call the new function and display result (sum) in console.log
  ========================================================================
  */
  async function addToSixAA() {
    let sum = await respondAfter100ms(1);
    sum += await respondAfter100ms(2);
    sum += await respondAfter100ms(3);
    return sum;
  }

  addToSixAA().then(sum => {
    console.log('addToSixAA returns', sum);
  });

  function addToThreeWithError() {
    let sum = 0;
    return respondAfter100ms(1)
      .then(one => {
        sum += one;
        return respondAfter100ms(-1);
      })
      .then(null, skulls => {
        console.error('Handling error:', skulls);
        return respondAfter100ms(2)
      })
      .then(two => {
        sum += two;
        return sum;
      });
  }

  addToThreeWithError().then(sum => {
    console.log('addToThreeWithError returns', sum);
  });

  /*
  ===================================================================================
  ðŸ‘‰ Rewrite `addToThreeWithError` function in a new function with async / await only
  ðŸ‘‰ Call the new function and display result (sum) in console.log
  ===================================================================================
  */
  async function addToThreeWithErrorAA() {
    let sum = await respondAfter100ms(1);
    try {
      await respondAfter100ms(-1);
    } catch (e) {
      console.error('Handling error:', e);
    }
    sum += await respondAfter100ms(2);
    return sum;
  }

  addToThreeWithErrorAA().then(sum => {
    console.log('addToThreeWithErrorAA returns', sum);
  });

}());
